<mujoco model="panda_allegro">
  <compiler angle="radian" autolimits="true"/>
  <option timestep=".002" noslip_iterations="5" noslip_tolerance="0"/>

  <!-- ========================= DEFAULTS (panda + allegro) ========================= -->
  <!-- panda defaults -->
  <default>
    <default class="panda">
      <joint armature="0.1" damping="1" axis="0 0 1" range="-2.8973 2.8973"/>
      <default class="panda/visual">
        <geom type="mesh" contype="0" conaffinity="0" group="2"/>
      </default>
      <default class="panda/collision">
        <geom type="mesh" group="3"/>
      </default>
      <site size="0.001" rgba="0.5 0.5 0.5 0.3" group="4"/>
    </default>
    <default class="2f85">
      <mesh scale="0.001 0.001 0.001"/>
      <general biastype="affine"/>
      <site type="sphere" rgba="0.9 0.9 0.9 1" size="0.005" group="4"/>
      <joint axis="1 0 0"/>
      <default class="driver">
        <joint range="0 0.8" armature="0.005" damping="0.1" solimplimit="0.95 0.99 0.001" solreflimit="0.005 1"/>
      </default>
      <default class="follower">
        <joint range="-0.872664 0.872664" pos="0 -0.018 0.0065" solimplimit="0.95 0.99 0.001" solreflimit="0.005 1"/>
      </default>
      <default class="spring_link">
        <joint range="-0.29670597283 0.8" stiffness="0.05" springref="2.62" damping="0.00125"/>
      </default>
      <default class="coupler">
        <joint range="-1.57 0" solimplimit="0.95 0.99 0.001" solreflimit="0.005 1"/>
      </default>
      <default class="2f85/visual">
        <geom type="mesh" contype="0" conaffinity="0" group="2"/>
      </default>
      <default class="2f85/collision">
        <geom type="mesh" group="3"/>
        <default class="pad_box1">
          <geom mass="0" type="box" pos="0 -0.0026 0.028125" size="0.011 0.004 0.009375" friction="0.7"
            solimp="0.95 0.99 0.001" solref="0.004 1" priority="1" rgba="0.55 0.55 0.55 1"/>
        </default>
        <default class="pad_box2">
          <geom mass="0" type="box" pos="0 -0.0026 0.009375" size="0.011 0.004 0.009375" friction="0.6"
            solimp="0.95 0.99 0.001" solref="0.004 1" priority="1" rgba="0.45 0.45 0.45 1"/>
        </default>
      </default>
    </default>
  </default>

  <!-- allegro defaults (kept mostly as-is) -->
  <default>
    <default class="allegro_right">
      <joint axis="0 1 0" damping=".1"/>
      <position kp="2"/>
      <geom density="800"/>

      <default class="visual">
        <geom type="mesh" contype="0" conaffinity="0" group="2" material="black"/>
        <default class="palm_visual">
          <geom mesh="base_link"/>
        </default>
        <default class="base_visual">
          <geom mesh="link_0.0"/>
        </default>
        <default class="proximal_visual">
          <geom mesh="link_1.0"/>
        </default>
        <default class="medial_visual">
          <geom mesh="link_2.0"/>
        </default>
        <default class="distal_visual">
          <geom mesh="link_3.0"/>
        </default>
        <default class="fingertip_visual">
          <geom pos="0 0 0.0267" material="white" mesh="link_3.0_tip"/>
        </default>
        <default class="thumbtip_visual">
          <geom pos="0 0 0.0423" material="white" mesh="link_15.0_tip"/>
        </default>
      </default>

      <default class="collision">
        <geom group="3" type="box" mass="0"/>
        <default class="palm_collision">
          <geom size="0.0204 0.0565 0.0475" pos="-0.0093 0 -0.0475"/>
        </default>
        <default class="base_collision">
          <geom size="0.0098 0.01375 0.0082" pos="0 0 0.0082"/>
          <default class="thumb_base_collision">
            <geom size="0.0179 0.017 0.02275" pos="-0.0179 0.009 0.0145"/>
          </default>
        </default>
        <default class="proximal_collision">
          <geom size="0.0098 0.01375 0.027" pos="0 0 0.027"/>
          <default class="thumb_proximal_collision">
            <geom size="0.0098 0.01375 0.00885" pos="0 0 0.00885"/>
          </default>
        </default>
        <default class="medial_collision">
          <geom size="0.0098 0.01375 0.0192" pos="0 0 0.0192"/>
          <default class="thumb_medial_collision">
            <geom size="0.0098 0.01375 0.0257" pos="0 0 0.0257"/>
          </default>
        </default>
        <default class="distal_collision">
          <geom size="0.0098 0.01375 0.008" pos="0 0 0.008"/>
          <default class="thumb_distal_collision">
            <geom size="0.0098 0.01375 0.0157" pos="0 0 0.0157"/>
          </default>
        </default>

        <default class="fingertip_collision">
          <geom type="capsule" size="0.012 0.01" pos="0 0 0.019"/>
          <default class="thumbtip_collision">
            <geom type="capsule" size="0.012 0.008" pos="0 0 0.035"/>
          </default>
        </default>
      </default>

      <default class="base">
        <joint axis="0 0 1" range="-0.47 0.47"/>
        <position ctrlrange="-0.47 0.47"/>
      </default>
      <default class="proximal">
        <joint range="-0.196 1.61"/>
        <position ctrlrange="-0.196 1.61"/>
      </default>
      <default class="medial">
        <joint range="-0.174 1.709"/>
        <position ctrlrange="-0.174 1.709"/>
      </default>
      <default class="distal">
        <joint range="-0.227 1.618"/>
        <position ctrlrange="-0.227 1.618"/>
      </default>
      <default class="thumb_base">
        <joint axis="-1 0 0" range="0.263 1.396"/>
        <position ctrlrange="0.263 1.396"/>
      </default>
      <default class="thumb_proximal">
        <joint axis="0 0 1" range="-0.105 1.163"/>
        <position ctrlrange="-0.105 1.163"/>
      </default>
      <default class="thumb_medial">
        <joint range="-0.189 1.644"/>
        <position ctrlrange="-0.189 1.644"/>
      </default>
      <default class="thumb_distal">
        <joint range="-0.162 1.719"/>
        <position ctrlrange="-0.162 1.719"/>
      </default>
    </default>
  </default>

  <!-- ========================= ASSETS (merge franka + allegro) ========================= -->
  <asset>
    <!-- panda assets -->
    <material name="white" rgba="1 1 1 1"/>
    <material name="off_white" rgba="0.901961 0.921569 0.929412 1"/>
    <material name="dark_grey" rgba="0.25 0.25 0.25 1"/>
    <material name="green" rgba="0 1 0 1"/>
    <material name="light_blue" rgba="0.039216 0.541176 0.780392 1"/>
    <material name="metal" rgba="0.58 0.58 0.58 1"/>
    <material name="silicone" rgba="0.1882 0.1882 0.1882 1"/>
    <material name="gray" rgba="0.4627 0.4627 0.4627 1"/>
    <material name="black" rgba="0.149 0.149 0.149 1"/>

    <mesh name="link0_c" file="franka_emika_panda/assets/link0.stl"/>
    <mesh name="link1_c" file="franka_emika_panda/assets/link1.stl"/>
    <mesh name="link2_c" file="franka_emika_panda/assets/link2.stl"/>
    <mesh name="link3_c" file="franka_emika_panda/assets/link3.stl"/>
    <mesh name="link4_c" file="franka_emika_panda/assets/link4.stl"/>
    <mesh name="link5_c0" file="franka_emika_panda/assets/link5_collision_0.obj"/>
    <mesh name="link5_c1" file="franka_emika_panda/assets/link5_collision_1.obj"/>
    <mesh name="link5_c2" file="franka_emika_panda/assets/link5_collision_2.obj"/>
    <mesh name="link6_c" file="franka_emika_panda/assets/link6.stl"/>
    <mesh name="link7_c" file="franka_emika_panda/assets/link7.stl"/>
    <mesh file="franka_emika_panda/assets/link0_0.obj"/>
    <mesh file="franka_emika_panda/assets/link0_1.obj"/>
    <mesh file="franka_emika_panda/assets/link0_2.obj"/>
    <mesh file="franka_emika_panda/assets/link0_3.obj"/>
    <mesh file="franka_emika_panda/assets/link0_4.obj"/>
    <mesh file="franka_emika_panda/assets/link0_5.obj"/>
    <mesh file="franka_emika_panda/assets/link0_7.obj"/>
    <mesh file="franka_emika_panda/assets/link0_8.obj"/>
    <mesh file="franka_emika_panda/assets/link0_9.obj"/>
    <mesh file="franka_emika_panda/assets/link0_10.obj"/>
    <mesh file="franka_emika_panda/assets/link0_11.obj"/>
    <mesh file="franka_emika_panda/assets/link1.obj"/>
    <mesh file="franka_emika_panda/assets/link2.obj"/>
    <mesh file="franka_emika_panda/assets/link3_0.obj"/>
    <mesh file="franka_emika_panda/assets/link3_1.obj"/>
    <mesh file="franka_emika_panda/assets/link3_2.obj"/>
    <mesh file="franka_emika_panda/assets/link3_3.obj"/>
    <mesh file="franka_emika_panda/assets/link4_0.obj"/>
    <mesh file="franka_emika_panda/assets/link4_1.obj"/>
    <mesh file="franka_emika_panda/assets/link4_2.obj"/>
    <mesh file="franka_emika_panda/assets/link4_3.obj"/>
    <mesh file="franka_emika_panda/assets/link5_0.obj"/>
    <mesh file="franka_emika_panda/assets/link5_1.obj"/>
    <mesh file="franka_emika_panda/assets/link5_2.obj"/>
    <mesh file="franka_emika_panda/assets/link6_0.obj"/>
    <mesh file="franka_emika_panda/assets/link6_1.obj"/>
    <mesh file="franka_emika_panda/assets/link6_2.obj"/>
    <mesh file="franka_emika_panda/assets/link6_3.obj"/>
    <mesh file="franka_emika_panda/assets/link6_4.obj"/>
    <mesh file="franka_emika_panda/assets/link6_5.obj"/>
    <mesh file="franka_emika_panda/assets/link6_6.obj"/>
    <mesh file="franka_emika_panda/assets/link6_7.obj"/>
    <mesh file="franka_emika_panda/assets/link6_8.obj"/>
    <mesh file="franka_emika_panda/assets/link6_9.obj"/>
    <mesh file="franka_emika_panda/assets/link6_10.obj"/>
    <mesh file="franka_emika_panda/assets/link6_11.obj"/>
    <mesh file="franka_emika_panda/assets/link6_12.obj"/>
    <mesh file="franka_emika_panda/assets/link6_13.obj"/>
    <mesh file="franka_emika_panda/assets/link6_14.obj"/>
    <mesh file="franka_emika_panda/assets/link6_15.obj"/>
    <mesh file="franka_emika_panda/assets/link6_16.obj"/>
    <mesh file="franka_emika_panda/assets/link7_0.obj"/>
    <mesh file="franka_emika_panda/assets/link7_1.obj"/>
    <mesh file="franka_emika_panda/assets/link7_2.obj"/>
    <mesh file="franka_emika_panda/assets/link7_3.obj"/>
    <mesh file="franka_emika_panda/assets/link7_4.obj"/>
    <mesh file="franka_emika_panda/assets/link7_5.obj"/>
    <mesh file="franka_emika_panda/assets/link7_6.obj"/>
    <mesh file="franka_emika_panda/assets/link7_7.obj"/>

    <!-- allegro assets -->
    <material name="allegro_black" rgba="0.2 0.2 0.2 1"/>
    <material name="allegro_white" rgba="0.9 0.9 0.9 1"/>
    <mesh file="wonik_allegro/assets/base_link.stl"/>
    <mesh file="wonik_allegro/assets/link_0.0.stl"/>
    <mesh file="wonik_allegro/assets/link_1.0.stl"/>
    <mesh file="wonik_allegro/assets/link_2.0.stl"/>
    <mesh file="wonik_allegro/assets/link_3.0.stl"/>
    <mesh file="wonik_allegro/assets/link_3.0_tip.stl"/>
    <mesh file="wonik_allegro/assets/link_12.0_right.stl"/>
    <mesh file="wonik_allegro/assets/link_13.0.stl"/>
    <mesh file="wonik_allegro/assets/link_14.0.stl"/>
    <mesh file="wonik_allegro/assets/link_15.0.stl"/>
    <mesh file="wonik_allegro/assets/link_15.0_tip.stl"/>

    <!-- rethink base assets -->
    <mesh name="pedestal" file="rethink_mount/pedestal.stl" />
  </asset>

  <!-- ========================= WORLDBODY (based on panda, allegro attached at attachment) ========================= -->
  <worldbody>
    <!-- <body name="base" pos="0 0 -0.924"> -->
    <body name="base" pos="-0.8 0 0.924">
      <body name="controller_box" pos="0 0 0">
          <inertial diaginertia="1.71363 1.27988 0.809981" mass="46.64" pos="-0.325 0 -0.38"/>
          <geom pos="-0.325 0 -0.38" size="0.11 0.2 0.265" type="box" name="controller_box_col" group="3"/>
      </body>
      <body name="pedestal_feet" pos="0 0 0">
          <inertial diaginertia="8.16095 9.59375 15.0785" mass="167.09" pos="-0.1225 0 -0.758"/>
          <geom pos="-0.1225 0 -0.758" size="0.385 0.35 0.155" type="box" name="pedestal_feet_col" group="3"/>
      </body>
      <body name="torso" pos="0 0 0">
          <inertial diaginertia="1e-08 1e-08 1e-08" mass="0.0001" pos="0 0 0"/>
          <geom conaffinity="0" contype="0" group="1" pos="0 0 -0.05" size="0.05 0.05 0.05" type="box" name="torso_vis" rgba="0.2 0.2 0.2 1" />
      </body>
      <body name="pedestal" pos="0 0 0">
          <inertial diaginertia="6.0869 5.81635 4.20915" mass="60.864" pos="0 0 0" quat="0.659267 -0.259505 -0.260945 0.655692"/>
          <geom conaffinity="0" contype="0" group="1" mesh="pedestal" type="mesh" name="pedestal_vis" rgba="0.2 0.2 0.2 1" />
          <geom pos="-0.02 0 -0.29" rgba="0.2 0.2 0.2 1" size="0.18 0.31" type="cylinder" name="pedestal_col" group="3"/>
      </body>
    <!-- scene helper (axes) optional -->
    <!-- begin panda structure (as in original) -->
      <body name="link0" pos="0.05 0 0" childclass="panda">
        <inertial mass="0.629769" pos="-0.041018 -0.00014 0.049974"
          fullinertia="0.00315 0.00388 0.004285 8.2904e-7 0.00015 8.2299e-6"/>
        <geom mesh="link0_0" material="off_white" class="panda/visual"/>
        <geom mesh="link0_1" material="dark_grey" class="panda/visual"/>
        <geom mesh="link0_2" material="off_white" class="panda/visual"/>
        <geom mesh="link0_3" material="dark_grey" class="panda/visual"/>
        <geom mesh="link0_4" material="off_white" class="panda/visual"/>
        <geom mesh="link0_5" material="dark_grey" class="panda/visual"/>
        <geom mesh="link0_7" material="white" class="panda/visual"/>
        <geom mesh="link0_8" material="white" class="panda/visual"/>
        <geom mesh="link0_9" material="dark_grey" class="panda/visual"/>
        <geom mesh="link0_10" material="off_white" class="panda/visual"/>
        <geom mesh="link0_11" material="white" class="panda/visual"/>
        <geom mesh="link0_c" class="panda/collision"/>
        <body name="link1" pos="0 0 0.333">
          <inertial mass="4.970684" pos="0.003875 0.002081 -0.04762"
            fullinertia="0.70337 0.70661 0.0091170 -0.00013900 0.0067720 0.019169"/>
          <joint name="joint1"/>
          <site name="joint1"/>
          <geom material="white" mesh="link1" class="panda/visual"/>
          <geom mesh="link1_c" class="panda/collision"/>
          <body name="link2" quat="1 -1 0 0">
            <inertial mass="0.646926" pos="-0.003141 -0.02872 0.003495"
              fullinertia="0.0079620 2.8110e-2 2.5995e-2 -3.925e-3 1.0254e-2 7.04e-4"/>
            <joint name="joint2" range="-1.7628 1.7628"/>
            <site name="joint2"/>
            <geom material="white" mesh="link2" class="panda/visual"/>
            <geom mesh="link2_c" class="panda/collision"/>
            <body name="link3" pos="0 -0.316 0" quat="1 1 0 0">
              <inertial mass="3.228604" pos="2.7518e-2 3.9252e-2 -6.6502e-2"
                fullinertia="3.7242e-2 3.6155e-2 1.083e-2 -4.761e-3 -1.1396e-2 -1.2805e-2"/>
              <joint name="joint3"/>
              <site name="joint3"/>
              <geom mesh="link3_0" material="white" class="panda/visual"/>
              <geom mesh="link3_1" material="white" class="panda/visual"/>
              <geom mesh="link3_2" material="white" class="panda/visual"/>
              <geom mesh="link3_3" material="dark_grey" class="panda/visual"/>
              <geom mesh="link3_c" class="panda/collision"/>
              <body name="link4" pos="0.0825 0 0" quat="1 1 0 0">
                <inertial mass="3.587895" pos="-5.317e-2 1.04419e-1 2.7454e-2"
                  fullinertia="2.5853e-2 1.9552e-2 2.8323e-2 7.796e-3 -1.332e-3 8.641e-3"/>
                <joint name="joint4" range="-3.0718 -0.0698"/>
                <site name="joint4"/>
                <geom mesh="link4_0" material="white" class="panda/visual"/>
                <geom mesh="link4_1" material="white" class="panda/visual"/>
                <geom mesh="link4_2" material="dark_grey" class="panda/visual"/>
                <geom mesh="link4_3" material="white" class="panda/visual"/>
                <geom mesh="link4_c" class="panda/collision"/>
                <body name="link5" pos="-0.0825 0.384 0" quat="1 -1 0 0">
                  <inertial mass="1.225946" pos="-1.1953e-2 4.1065e-2 -3.8437e-2"
                    fullinertia="3.5549e-2 2.9474e-2 8.627e-3 -2.117e-3 -4.037e-3 2.29e-4"/>
                  <joint name="joint5"/>
                  <site name="joint5"/>
                  <geom mesh="link5_0" material="dark_grey" class="panda/visual"/>
                  <geom mesh="link5_1" material="white" class="panda/visual"/>
                  <geom mesh="link5_2" material="white" class="panda/visual"/>
                  <geom mesh="link5_c0" class="panda/collision"/>
                  <geom mesh="link5_c1" class="panda/collision"/>
                  <geom mesh="link5_c2" class="panda/collision"/>
                  <body name="link6" quat="1 1 0 0">
                    <inertial mass="1.666555" pos="6.0149e-2 -1.4117e-2 -1.0517e-2"
                      fullinertia="1.964e-3 4.354e-3 5.433e-3 1.09e-4 -1.158e-3 3.41e-4"/>
                    <joint name="joint6" range="-0.0175 3.7525"/>
                    <site name="joint6"/>
                    <geom mesh="link6_0" material="off_white" class="panda/visual"/>
                    <geom mesh="link6_1" material="white" class="panda/visual"/>
                    <geom mesh="link6_2" material="dark_grey" class="panda/visual"/>
                    <geom mesh="link6_3" material="white" class="panda/visual"/>
                    <geom mesh="link6_4" material="white" class="panda/visual"/>
                    <geom mesh="link6_5" material="white" class="panda/visual"/>
                    <geom mesh="link6_6" material="white" class="panda/visual"/>
                    <geom mesh="link6_7" material="light_blue" class="panda/visual"/>
                    <geom mesh="link6_8" material="light_blue" class="panda/visual"/>
                    <geom mesh="link6_9" material="dark_grey" class="panda/visual"/>
                    <geom mesh="link6_10" material="dark_grey" class="panda/visual"/>
                    <geom mesh="link6_11" material="white" class="panda/visual"/>
                    <geom mesh="link6_12" material="green" class="panda/visual"/>
                    <geom mesh="link6_13" material="white" class="panda/visual"/>
                    <geom mesh="link6_14" material="dark_grey" class="panda/visual"/>
                    <geom mesh="link6_15" material="dark_grey" class="panda/visual"/>
                    <geom mesh="link6_16" material="white" class="panda/visual"/>
                    <geom mesh="link6_c" class="panda/collision"/>
                    <body name="link7" pos="0.088 0 0" quat="1 1 0 0">
                      <inertial mass="7.35522e-01" pos="1.0517e-2 -4.252e-3 6.1597e-2"
                        fullinertia="1.2516e-2 1.0027e-2 4.815e-3 -4.28e-4 -1.196e-3 -7.41e-4"/>
                      <joint name="joint7"/>
                      <site name="joint7"/>
                      <geom mesh="link7_0" material="white" class="panda/visual"/>
                      <geom mesh="link7_1" material="dark_grey" class="panda/visual"/>
                      <geom mesh="link7_2" material="dark_grey" class="panda/visual"/>
                      <geom mesh="link7_3" material="dark_grey" class="panda/visual"/>
                      <geom mesh="link7_4" material="dark_grey" class="panda/visual"/>
                      <geom mesh="link7_5" material="dark_grey" class="panda/visual"/>
                      <geom mesh="link7_6" material="dark_grey" class="panda/visual"/>
                      <geom mesh="link7_7" material="white" class="panda/visual"/>
                      <geom mesh="link7_c" class="panda/collision"/>

                      <!-- attachment point on panda wrist -->
                      <body name="attachment" pos="0 0 0.107" quat="0.3826834 0 0 0.9238795">
                        <camera name="handcam_rgb" pos="0.14 0.03 0.04" fovy="60" quat="-0.353553 0.612372 -0.612372 0.352553"/>
                        <site name="attachment_site" quat="0 0 0 1"/>

                        <!-- === REPLACE: mount/gripper replaced by Allegro hand === -->
                        <!-- allegro is attached here. adjust pos/euler if needed to align. -->
                        <body name="allegro_attachment">
                          <!-- Use palm as root, keep inner finger/body names intact -->
                          
                          <!-- <body name="allegro_palm" pos="-0.05 0.0 0.03" quat="0.707 0 -0.707 0" childclass="allegro_right">  -->
                          <body name="allegro_palm" pos="-0.05 0.0 0.03" quat="0.707 0 -0.707 0" childclass="allegro_right"> 
                          <!-- <body name="allegro_palm" pos="0.01 0 0.09" quat="1 0 0 0" childclass="allegro_right"> -->
                            <!-- optional inertial if you want to set -->

                            <geom class="palm_visual" mesh="base_link"/>
                            <geom class="palm_collision"/>

                            <!-- First finger -->
                            <body name="ff_base" pos="0 0.0435 -0.001542" quat="0.999048 -0.0436194 0 0">
                              <joint name="ffj0" class="base"/>
                              <geom class="base_visual"/>
                              <geom class="base_collision"/>
                              <body name="ff_proximal" pos="0 0 0.0164">
                                <joint name="ffj1" class="proximal"/>
                                <geom class="proximal_visual"/>
                                <geom class="proximal_collision"/>
                                <body name="ff_medial" pos="0 0 0.054">
                                  <joint name="ffj2" class="medial"/>
                                  <geom class="medial_visual"/>
                                  <geom class="medial_collision"/>
                                  <body name="ff_distal" pos="0 0 0.0384">
                                    <joint name="ffj3" class="distal"/>
                                    <geom class="distal_visual"/>
                                    <geom class="distal_collision"/>
                                    <body name="ff_tip">
                                      <geom class="fingertip_visual"/>
                                      <geom class="fingertip_collision"/>
                                      
                                      <!-- <site name="index_tip" pos="-0.00 -0.0 0.0" size="0.02" rgba="0 1 0 1"/> -->
                                    </body>
                                  </body>
                                </body>
                              </body>
                            </body>

                            <!-- Middle finger -->
                            <body name="mf_base" pos="0 0 0.0007">
                              <joint name="mfj0" class="base"/>
                              <geom class="base_visual"/>
                              <geom class="base_collision"/>
                              <body name="mf_proximal" pos="0 0 0.0164">
                                <joint name="mfj1" class="proximal"/>
                                <geom class="proximal_visual"/>
                                <geom class="proximal_collision"/>
                                <body name="mf_medial" pos="0 0 0.054">
                                  <joint name="mfj2" class="medial"/>
                                  <geom class="medial_visual"/>
                                  <geom class="medial_collision"/>
                                  <body name="mf_distal" pos="0 0 0.0384">
                                    <joint name="mfj3" class="distal"/>
                                    <geom class="distal_visual"/>
                                    <geom class="distal_collision"/>
                                    <body name="mf_tip">
                                      <geom class="fingertip_visual"/>
                                      <geom class="fingertip_collision"/>
                                      
                                      <!-- <site name="middle_tip" pos="-0.0 - - - - - - - - - - - - - - - - " size=" " rgba=" " /> -->
                                    </body>
                                  </body>
                                </body>
                              </body>
                            </body>

                            <!-- Ring finger -->
                            <body name="rf_base" pos="0 -0.0435 -0.001542" quat="0.999048 0.0436194 0 0">
                              <joint name="rfj0" class="base"/>
                              <geom class="base_visual"/>
                              <geom class="base_collision"/>
                              <body name="rf_proximal" pos="0 0 0.0164">
                                <joint name="rfj1" class="proximal"/>
                                <geom class="proximal_visual"/>
                                <geom class="proximal_collision"/>
                                <body name="rf_medial" pos="0 0 0.054">
                                  <joint name="rfj2" class="medial"/>
                                  <geom class="medial_visual"/>
                                  <geom class="medial_collision"/>
                                  <body name="rf_distal" pos="0 0 0.0384">
                                    <joint name="rfj3" class="distal"/>
                                    <geom class="distal_visual"/>
                                    <geom class="distal_collision"/>
                                    <body name="rf_tip">
                                      <geom class="fingertip_visual"/>
                                      <geom class="fingertip_collision"/>
                                    
                                      <!-- <site name="ring_tip" pos="-0.00 -0.0 0.0" size="0.02" rgba="0 1 0 1"/> -->
                                    </body>
                                  </body>
                                </body>
                              </body>
                            </body>

                            <!-- Thumb -->
                            <body name="th_base" pos="-0.0182 0.019333 -0.045987" quat="0.477714 -0.521334 -0.521334 -0.477714">
                              <joint name="thj0" class="thumb_base"/>
                              <geom class="visual" mesh="link_12.0_right"/>
                              <geom class="thumb_base_collision"/>
                              <body name="th_proximal" pos="-0.027 0.005 0.0399">
                                <joint name="thj1" class="thumb_proximal"/>
                                <geom class="visual" mesh="link_13.0"/>
                                <geom class="thumb_proximal_collision"/>
                                <body name="th_medial" pos="0 0 0.0177">
                                  <joint name="thj2" class="thumb_medial"/>
                                  <geom class="visual" mesh="link_14.0"/>
                                  <geom class="thumb_medial_collision"/>
                                  <body name="th_distal" pos="0 0 0.0514">
                                    <joint name="thj3" class="thumb_distal"/>
                                    <geom class="visual" mesh="link_15.0"/>
                                    <geom class="thumb_distal_collision"/>
                                    <body name="th_tip">
                                      <geom class="thumbtip_visual"/>
                                      <geom class="thumbtip_collision"/>
                          
                                      <site name="th_pad_site" pos="0 0 0.012" size="0.003" rgba="0 1 0 0.3"/>
                                      <!-- <site name="thumb_tip" pos="-0.00 -0. -0.0" size="0.02" rgba="0 1 0 1"/> -->
                                    </body>
                                  </body>
                                </body>
                              </body>
                            </body>

                          </body><!-- allegro_palm -->
                        </body><!-- allegro_attachment -->
                      </body><!-- attachment -->
                    </body><!-- link7 -->
                  </body><!-- link6 -->
                </body><!-- link5 -->
              </body><!-- link4 -->
            </body><!-- link3 -->
          </body><!-- link2 -->
        </body><!-- link1 -->
      </body><!-- link0 -->
    </body><!-- base -->

  </worldbody>

  <!-- ========================= CONTACT (merge, adjust allegro palm name) ========================= -->
  <contact>
    <!-- panda original excludes -->
   
    <!-- allegro excludes: update palm -> allegro_palm -->
    <exclude body1="allegro_palm" body2="ff_base"/>
    <exclude body1="allegro_palm" body2="mf_base"/>
    <exclude body1="allegro_palm" body2="rf_base"/>
    <exclude body1="allegro_palm" body2="th_base"/>
    <exclude body1="allegro_palm" body2="th_proximal"/>
  </contact>

  <!-- ========================= TENDON / EQUALITY (keep panda ones) ========================= -->


  <!-- ========================= ACTUATORS (panda + allegro actuators) ========================= -->
  <actuator>
    <!-- panda actuators -->
    <motor class="panda" name="actuator1" joint="joint1" ctrlrange="-87 87"/>
    <motor class="panda" name="actuator2" joint="joint2" ctrlrange="-87 87"/>
    <motor class="panda" name="actuator3" joint="joint3" ctrlrange="-87 87"/>
    <motor class="panda" name="actuator4" joint="joint4" ctrlrange="-87 87"/>
    <motor class="panda" name="actuator5" joint="joint5" ctrlrange="-12 12"/>
    <motor class="panda" name="actuator6" joint="joint6" ctrlrange="-12 12"/>
    <motor class="panda" name="actuator7" joint="joint7" ctrlrange="-12 12"/>
    

    <!-- allegro actuators -->
    <position name="ffa0" joint="ffj0" class="base"/>
    <position name="ffa1" joint="ffj1" class="proximal"/>
    <position name="ffa2" joint="ffj2" class="medial"/>
    <position name="ffa3" joint="ffj3" class="distal"/>
    <position name="mfa0" joint="mfj0" class="base"/>
    <position name="mfa1" joint="mfj1" class="proximal"/>
    <position name="mfa2" joint="mfj2" class="medial"/>
    <position name="mfa3" joint="mfj3" class="distal"/>
    <position name="rfa0" joint="rfj0" class="base"/>
    <position name="rfa1" joint="rfj1" class="proximal"/>
    <position name="rfa2" joint="rfj2" class="medial"/>
    <position name="rfa3" joint="rfj3" class="distal"/>
    <position name="tha0" joint="thj0" class="thumb_base"/>
    <position name="tha1" joint="thj1" class="thumb_proximal"/>
    <position name="tha2" joint="thj2" class="thumb_medial"/>
    <position name="tha3" joint="thj3" class="thumb_distal"/>
  </actuator>

  <!-- ========================= SENSORS (merge) ========================= -->
  <sensor>
    <!-- panda sensors -->
    <jointpos name="panda/joint1_pos" joint="joint1"/>
    <jointpos name="panda/joint2_pos" joint="joint2"/>
    <jointpos name="panda/joint3_pos" joint="joint3"/>
    <jointpos name="panda/joint4_pos" joint="joint4"/>
    <jointpos name="panda/joint5_pos" joint="joint5"/>
    <jointpos name="panda/joint6_pos" joint="joint6"/>
    <jointpos name="panda/joint7_pos" joint="joint7"/>

    <jointvel name="panda/joint1_vel" joint="joint1"/>
    <jointvel name="panda/joint2_vel" joint="joint2"/>
    <jointvel name="panda/joint3_vel" joint="joint3"/>
    <jointvel name="panda/joint4_vel" joint="joint4"/>
    <jointvel name="panda/joint5_vel" joint="joint5"/>
    <jointvel name="panda/joint6_vel" joint="joint6"/>
    <jointvel name="panda/joint7_vel" joint="joint7"/>

    <torque name="panda/joint1_torque" site="joint1"/>
    <torque name="panda/joint2_torque" site="joint2"/>
    <torque name="panda/joint3_torque" site="joint3"/>
    <torque name="panda/joint4_torque" site="joint4"/>
    <torque name="panda/joint5_torque" site="joint5"/>
    <torque name="panda/joint6_torque" site="joint6"/>
    <torque name="panda/joint7_torque" site="joint7"/>

    <force name="panda/wrist_force" site="attachment_site"/>

      <!-- Franka end-effector (flange) frame outputs -->
    <framepos     name="franka/flange_pos"     objtype="site" objname="attachment_site"/>
    <framequat    name="franka/flange_quat"    objtype="site" objname="attachment_site"/>
    <framelinvel  name="franka/flange_vel"     objtype="site" objname="attachment_site"/>

      <!-- allegro sensors -->
    <jointpos name="allegro_right/ffj0_pos" joint="ffj0"/>
    <jointpos name="allegro_right/ffj1_pos" joint="ffj1"/>
    <jointpos name="allegro_right/ffj2_pos" joint="ffj2"/>
    <jointpos name="allegro_right/ffj3_pos" joint="ffj3"/>
    <jointpos name="allegro_right/mfj0_pos" joint="mfj0"/>
    <jointpos name="allegro_right/mfj1_pos" joint="mfj1"/>
    <jointpos name="allegro_right/mfj2_pos" joint="mfj2"/>
    <jointpos name="allegro_right/mfj3_pos" joint="mfj3"/>
    <jointpos name="allegro_right/rfj0_pos" joint="rfj0"/>
    <jointpos name="allegro_right/rfj1_pos" joint="rfj1"/>
    <jointpos name="allegro_right/rfj2_pos" joint="rfj2"/>
    <jointpos name="allegro_right/rfj3_pos" joint="rfj3"/>
    <jointpos name="allegro_right/thj0_pos" joint="thj0"/>
    <jointpos name="allegro_right/thj1_pos" joint="thj1"/>
    <jointpos name="allegro_right/thj2_pos" joint="thj2"/>
    <jointpos name="allegro_right/thj3_pos" joint="thj3"/>
  </sensor>

</mujoco>
