<mujoco model="partnet_101293">
  <option iterations="50" timestep="0.001" solver="PGS" gravity="0 0 -9.81" />
  <compiler angle="radian" meshdir="textured_objs_thickness" eulerseq="zyx" autolimits="true" />
  <default>
    <mesh scale="0.1 0.1 0.1" />
    <joint limited="true" damping="0.01" armature="0.01" frictionloss="0.01" />
    <motor ctrllimited="true" />
    <equality solref="0.001 2" />
    <default class="visual">
      <geom condim="1" contype="0" conaffinity="0" group="2" />
    </default>
    <default class="collision">
      <geom condim="4" contype="1" conaffinity="14" friction="0.9 0.2 0.2" solref="0.001 2" group="3" />
    </default>
  </default>
  <asset>
    <material name="original-2_material_0_0" specular="0.06666666666666667" shininess="0.03" rgba="0.11372549019607843 0.11372549019607843 0.11372549019607843 1" />
    <mesh file="original-2/original-2.obj" name="original-2" />
    <material name="original-1_1_material_0_0" specular="0.06666666666666667" shininess="0.03" rgba="0.11372549019607843 0.11372549019607843 0.11372549019607843 1" />
    <material name="original-1_0_material_1_0" specular="0.06666666666666667" shininess="0.03" rgba="0 0 0 1" />
    <mesh file="original-1/original-1_0.obj" name="original-1_0" />
    <mesh file="original-1/original-1_1.obj" name="original-1_1" />
    <material name="original-3_material_0_0" specular="0.06666666666666667" shininess="0.03" rgba="0.11372549019607843 0.11372549019607843 0.11372549019607843 1" />
    <mesh file="original-3/original-3.obj" name="original-3" />
  </asset>
  <worldbody>
    <light directional="true" pos="0 0 0.05" dir="0 0 -1" castshadow="false" />
    <body name="link_2" pos="0.0 0.0 0.0" quat="0.4999999999999998 0.5 -0.5000000000000002 -0.5">
      <geom pos="0.0 0.0 0.0" quat="1 0 0 0" type="mesh" mesh="original-1_0" material="original-1_0_material_1_0" density="0" class="visual" />
      <geom pos="0.0 0.0 0.0" quat="1 0 0 0" type="mesh" mesh="original-1_1" material="original-1_1_material_0_0" density="0" class="visual" />
      <geom pos="0.0 0.0 0.0" quat="1 0 0 0" type="mesh" mesh="original-1_0" material="original-1_0_material_1_0" class="collision" />
      <geom pos="0.0 0.0 0.0" quat="1 0 0 0" type="mesh" mesh="original-1_1" material="original-1_1_material_0_0" class="collision" />
      <body name="link_0" pos="-0.05822870119362571 0.012772445263971878 0.025211727978494827">
        <joint name="joint_0" pos="0 0 0" axis="0 -1 0" range="-0.0 1.3823007675795087" type="hinge" />
        <geom pos="0.05822870119362571 -0.012772445263971878 -0.025211727978494827" quat="1 0 0 0" type="mesh" mesh="original-3" material="original-3_material_0_0" density="0" class="visual" />
        <geom pos="0.05822870119362571 -0.012772445263971878 -0.025211727978494827" quat="1 0 0 0" type="mesh" mesh="original-3" material="original-3_material_0_0" class="collision" />
      </body>
      <body name="link_1" pos="0.06172104681835892 0.012821442256062455 0.025883854335217473">
        <joint name="joint_1" pos="0 0 0" axis="0 1 0" range="0.0 1.2915436464758039" type="hinge" />
        <geom pos="-0.06172104681835892 -0.012821442256062455 -0.025883854335217473" quat="1 0 0 0" type="mesh" mesh="original-2" material="original-2_material_0_0" density="0" class="visual" />
        <geom pos="-0.06172104681835892 -0.012821442256062455 -0.025883854335217473" quat="1 0 0 0" type="mesh" mesh="original-2" material="original-2_material_0_0" class="collision" />
      </body>
    </body>
  </worldbody>
  <actuator>
    <motor name="joint_0" joint="joint_0" ctrllimited="true" ctrlrange="-1 1" gear="1" />
    <motor name="joint_1" joint="joint_1" ctrllimited="true" ctrlrange="-1 1" gear="1" />
  </actuator>
</mujoco>
