<mujoco model="partnet_4589">
  <option iterations="50" timestep="0.001" solver="PGS" gravity="0 0 -9.81" />
  <compiler angle="radian" meshdir="textured_objs_thickness" eulerseq="zyx" autolimits="true" />
  <default>
    <mesh scale="0.1 0.1 0.1" />
    <joint limited="true" damping="0.01" armature="0.01" frictionloss="0.01" />
    <motor ctrllimited="true" />
    <equality solref="0.001 2" />
    <default class="visual">
      <geom condim="1" contype="0" conaffinity="0" group="2" />
    </default>
    <default class="collision">
      <geom condim="4" contype="1" conaffinity="14" friction="0.9 0.2 0.2" solref="0.001 2" group="3" />
    </default>
  </default>
  <asset>
    <material name="original-15_material_0_0" specular="0.06666666666666667" shininess="0.03" rgba="0.11372549019607843 0.11372549019607843 0.11372549019607843 1" />
    <mesh file="original-15/original-15.obj" name="original-15" />
    <material name="original-5_material_0_0" specular="0.06666666666666667" shininess="0.03" rgba="0.11372549019607843 0.11372549019607843 0.11372549019607843 1" />
    <mesh file="original-5/original-5.obj" name="original-5" />
    <material name="original-10_material_0_0" specular="0.06666666666666667" shininess="0.03" rgba="0.11372549019607843 0.11372549019607843 0.11372549019607843 1" />
    <mesh file="original-10/original-10.obj" name="original-10" />
    <material name="original-8_material_0_0" specular="0.06666666666666667" shininess="0.03" rgba="0.11372549019607843 0.11372549019607843 0.11372549019607843 1" />
    <mesh file="original-8/original-8.obj" name="original-8" />
    <material name="new-1_material-0" specular="0.06666666666666667" shininess="0.03" rgba="0.11372549019607843 0.11372549019607843 0.11372549019607843 1" />
    <mesh file="new-1/new-1.obj" name="new-1" />
    <material name="original-9_material_0_0" specular="0.06666666666666667" shininess="0.03" rgba="0.11372549019607843 0.11372549019607843 0.11372549019607843 1" />
    <mesh file="original-9/original-9.obj" name="original-9" />
    <material name="original-4_material_0_0" specular="0.06666666666666667" shininess="0.03" rgba="0.11372549019607843 0.11372549019607843 0.11372549019607843 1" />
    <mesh file="original-4/original-4.obj" name="original-4" />
    <material name="original-14_material_0_0" specular="0.06666666666666667" shininess="0.03" rgba="0.11372549019607843 0.11372549019607843 0.11372549019607843 1" />
    <mesh file="original-14/original-14.obj" name="original-14" />
    <material name="original-6_material_0_0" specular="0.06666666666666667" shininess="0.03" rgba="0.11372549019607843 0.11372549019607843 0.11372549019607843 1" />
    <mesh file="original-6/original-6.obj" name="original-6" />
    <material name="original-11_material_0_0" specular="0.06666666666666667" shininess="0.03" rgba="0.11372549019607843 0.11372549019607843 0.11372549019607843 1" />
    <mesh file="original-11/original-11.obj" name="original-11" />
    <material name="new-0_material-0" specular="0.06666666666666667" shininess="0.03" rgba="0.11372549019607843 0.11372549019607843 0.11372549019607843 1" />
    <mesh file="new-0/new-0.obj" name="new-0" />
    <material name="original-3_material_0_0" specular="0.06666666666666667" shininess="0.03" rgba="0.11372549019607843 0.11372549019607843 0.11372549019607843 1" />
    <mesh file="original-3/original-3.obj" name="original-3" />
  </asset>
  <worldbody>
    <light directional="true" pos="0 0 0.05" dir="0 0 -1" castshadow="false" />
    <body name="link_1" pos="0.0 0.0 0.0" quat="0.4999999999999998 0.5 -0.5000000000000002 -0.5">
      <geom pos="0.0 0.0 0.0" quat="1 0 0 0" type="mesh" mesh="original-15" material="original-15_material_0_0" density="0" class="visual" />
      <geom pos="0.0 0.0 0.0" quat="1 0 0 0" type="mesh" mesh="original-14" material="original-14_material_0_0" density="0" class="visual" />
      <geom pos="0.0 0.0 0.0" quat="1 0 0 0" type="mesh" mesh="original-15" material="original-15_material_0_0" class="collision" />
      <geom pos="0.0 0.0 0.0" quat="1 0 0 0" type="mesh" mesh="original-14" material="original-14_material_0_0" class="collision" />
      <body name="link_0" pos="0.009387200000000063 -0.015523215990950332 -0.007618436310905705">
        <joint name="joint_0" pos="0 0 0" axis="-1 0 0" range="-0.0 0.4363323129985824" type="hinge" />
        <geom pos="-0.009387200000000063 0.015523215990950332 0.007618436310905705" quat="1 0 0 0" type="mesh" mesh="original-4" material="original-4_material_0_0" density="0" class="visual" />
        <geom pos="-0.009387200000000063 0.015523215990950332 0.007618436310905705" quat="1 0 0 0" type="mesh" mesh="original-3" material="original-3_material_0_0" density="0" class="visual" />
        <geom pos="-0.009387200000000063 0.015523215990950332 0.007618436310905705" quat="1 0 0 0" type="mesh" mesh="new-1" material="new-1_material-0" density="0" class="visual" />
        <geom pos="-0.009387200000000063 0.015523215990950332 0.007618436310905705" quat="1 0 0 0" type="mesh" mesh="original-5" material="original-5_material_0_0" density="0" class="visual" />
        <geom pos="-0.009387200000000063 0.015523215990950332 0.007618436310905705" quat="1 0 0 0" type="mesh" mesh="original-6" material="original-6_material_0_0" density="0" class="visual" />
        <geom pos="-0.009387200000000063 0.015523215990950332 0.007618436310905705" quat="1 0 0 0" type="mesh" mesh="original-8" material="original-8_material_0_0" density="0" class="visual" />
        <geom pos="-0.009387200000000063 0.015523215990950332 0.007618436310905705" quat="1 0 0 0" type="mesh" mesh="original-9" material="original-9_material_0_0" density="0" class="visual" />
        <geom pos="-0.009387200000000063 0.015523215990950332 0.007618436310905705" quat="1 0 0 0" type="mesh" mesh="original-10" material="original-10_material_0_0" density="0" class="visual" />
        <geom pos="-0.009387200000000063 0.015523215990950332 0.007618436310905705" quat="1 0 0 0" type="mesh" mesh="original-11" material="original-11_material_0_0" density="0" class="visual" />
        <geom pos="-0.009387200000000063 0.015523215990950332 0.007618436310905705" quat="1 0 0 0" type="mesh" mesh="new-0" material="new-0_material-0" density="0" class="visual" />
        <geom pos="-0.009387200000000063 0.015523215990950332 0.007618436310905705" quat="1 0 0 0" type="mesh" mesh="original-4" material="original-4_material_0_0" class="collision" />
        <geom pos="-0.009387200000000063 0.015523215990950332 0.007618436310905705" quat="1 0 0 0" type="mesh" mesh="original-3" material="original-3_material_0_0" class="collision" />
        <geom pos="-0.009387200000000063 0.015523215990950332 0.007618436310905705" quat="1 0 0 0" type="mesh" mesh="new-1" material="new-1_material-0" class="collision" />
        <geom pos="-0.009387200000000063 0.015523215990950332 0.007618436310905705" quat="1 0 0 0" type="mesh" mesh="original-5" material="original-5_material_0_0" class="collision" />
        <geom pos="-0.009387200000000063 0.015523215990950332 0.007618436310905705" quat="1 0 0 0" type="mesh" mesh="original-6" material="original-6_material_0_0" class="collision" />
        <geom pos="-0.009387200000000063 0.015523215990950332 0.007618436310905705" quat="1 0 0 0" type="mesh" mesh="original-8" material="original-8_material_0_0" class="collision" />
        <geom pos="-0.009387200000000063 0.015523215990950332 0.007618436310905705" quat="1 0 0 0" type="mesh" mesh="original-9" material="original-9_material_0_0" class="collision" />
        <geom pos="-0.009387200000000063 0.015523215990950332 0.007618436310905705" quat="1 0 0 0" type="mesh" mesh="original-10" material="original-10_material_0_0" class="collision" />
        <geom pos="-0.009387200000000063 0.015523215990950332 0.007618436310905705" quat="1 0 0 0" type="mesh" mesh="original-11" material="original-11_material_0_0" class="collision" />
        <geom pos="-0.009387200000000063 0.015523215990950332 0.007618436310905705" quat="1 0 0 0" type="mesh" mesh="new-0" material="new-0_material-0" class="collision" />
      </body>
    </body>
  </worldbody>
  <actuator>
    <motor name="joint_0" joint="joint_0" ctrllimited="true" ctrlrange="-1 1" gear="1" />
  </actuator>
</mujoco>
