<mujoco model="bucket">
  <compiler angle="radian" eulerseq="zyx" autolimits="true" />
  <default>
    <default class="bucket">
      <mesh scale="0.25 0.25 0.25" />
      <joint limited="true" damping="0.01" armature="0.01" frictionloss="0.01" />
      <motor ctrllimited="true" />
      <equality solref="0.001 2" />
      <default class="bucket/visual">
        <geom condim="1" contype="0" conaffinity="0" group="2" />
      </default>
      <default class="bucket/collision">
        <geom condim="3" solref="0.001 2" group="3" />
      </default>
    </default>
  </default>
  <asset>
    <material name="bucket_original-5_material_0_0" specular="0.06666666666666667" shininess="0.03" rgba="1 0 0 1" />
    <mesh file="bucket/textured_objs_thickness/original-5/original-5.obj" name="bucket_original-5" scale="0.25 0.25 0.25" />
    <material name="bucket_original-1_1_material_0_0" specular="0.06666666666666667" shininess="0.03" rgba="1 0 0 1" />
    <material name="bucket_original-1_0_material_1_0" specular="0.06666666666666667" shininess="0.03" rgba="0 0 0 1" />
    <mesh file="bucket/textured_objs_thickness/original-1/original-1_0.obj" name="bucket_original-1_0" scale="0.25 0.25 0.25" />
    <mesh file="bucket/textured_objs_thickness/original-1/original-1_1.obj" name="bucket_original-1_1" scale="0.25 0.25 0.25" />
    <material name="bucket_original-4_material_0_0" specular="0.06666666666666667" shininess="0.03" rgba="1 0 0 1" />
    <mesh file="bucket/textured_objs_thickness/original-4/original-4.obj" name="bucket_original-4" scale="0.25 0.25 0.25" />
    <material name="bucket_original-3_material_0_0" specular="0.06666666666666667" shininess="0.03" rgba="1 0 0 1" />
    <mesh file="bucket/textured_objs_thickness/original-3/original-3.obj" name="bucket_original-3" scale="0.25 0.25 0.25" />
  </asset>
  <worldbody>
    <light directional="true" pos="0 0 0.5" dir="0 0 -1" castshadow="false" />
    <body name="bucket" pos="-0.2 0 1.0" quat="0 0 -0.7071 -0.7071" childclass="bucket">
      <freejoint name="bucket_root" />
      <site name="bucket_ref_0" pos="-0.18 -0.08 -0.13" size="0.01" rgba="1 0 0 0"/>
      <site name="bucket_ref_1" pos="-0.18 -0.08  0.12" size="0.01" rgba="1 0 0 0"/>
      <site name="bucket_ref_2" pos="-0.18  0.09 -0.13" size="0.01" rgba="1 0 0 0"/>
      <site name="bucket_ref_3" pos="-0.18  0.09  0.12" size="0.01" rgba="1 0 0 0"/>

      <site name="bucket_ref_4" pos=" 0.16 -0.08 -0.13" size="0.01" rgba="1 0 0 0"/>
      <site name="bucket_ref_5" pos=" 0.16 -0.08  0.12" size="0.01" rgba="1 0 0 0"/>
      <site name="bucket_ref_6" pos=" 0.16  0.09 -0.13" size="0.01" rgba="1 0 0 0"/>
      <site name="bucket_ref_7" pos=" 0.16  0.09  0.12" size="0.01" rgba="1 0 0 0"/>
      <geom pos="0.0 0.0 0.0" quat="1 0 0 0" type="mesh" mesh="bucket_original-4" material="bucket_original-4_material_0_0" density="0" class="bucket/visual" />
      <geom pos="0.0 0.0 0.0" quat="1 0 0 0" type="mesh" mesh="bucket_original-3" material="bucket_original-3_material_0_0" density="0" class="bucket/visual" />
      <geom pos="0.0 0.0 0.0" quat="1 0 0 0" type="mesh" mesh="bucket_original-5" material="bucket_original-5_material_0_0" density="0" class="bucket/visual" />
      <body name="bucket_link_0" pos="-0.002209335104562346 0.03504974806266648 0.0">
        <joint name="bucket_joint_0" pos="-0.005 0.055 0" axis="0 0 1" range="0.0 3.141592653589793" type="hinge" />
        <geom pos="0.002209335104562346 -0.03504974806266648 0.0" quat="1 0 0 0" type="mesh" mesh="bucket_original-1_0" material="bucket_original-1_0_material_1_0" density="0" class="bucket/visual" />
        <geom pos="0.002209335104562346 -0.03504974806266648 0.0" quat="1 0 0 0" type="mesh" mesh="bucket_original-1_1" material="bucket_original-1_1_material_0_0" density="0" class="bucket/visual" />
        <geom name="handle1" type="box" size="0.002 0.008 0.12" pos="0.175 0.053 -0.005" class="bucket/collision" />
        <geom name="handle2" type="box" size="0.09 0.008 0.0014" pos="0.085 0.053 -0.122" class="bucket/collision" />
        <geom name="handle3" type="box" size="0.09 0.008 0.0014" pos="0.085 0.053 0.113" class="bucket/collision" />
      </body>
    <geom name="bucket_back" type="box" size="0.195 0.09 0.004" pos="-0.01 0.01 -0.129" class="bucket/collision" />
    <geom name="bucket_front" type="box" size="0.195 0.09 0.004" pos="-0.01 0.01 0.12" class="bucket/collision" />
    <geom name="bucket_l" type="box" size="0.003 0.015 0.128" pos="-0.2 0.085 -0.005" class="bucket/collision" />
    <geom name="bucket_r" type="box" size="0.003 0.015 0.128" pos="0.183 0.085 -0.005" class="bucket/collision" />
    <geom name="bucket_left" type="box" size="0.001 0.09 0.128" quat="0.996566 0.000000 0.000000 0.082808" pos="-0.183 0.01 -0.005" mass="0.05" class="bucket/collision" />
    <geom name="bucket_right" type="box" size="0.001 0.09 0.128" quat="0.997503 0.000000 0.000000 -0.070627" pos="0.168 0.01 -0.005" mass="0.05" class="bucket/collision" />
    <geom name="bucket_bottom" type="box" size="0.163 0.002 0.12" pos="-0.007 -0.078 -0.005" class="bucket/collision" rgba="1 0 0 1" group="1" />
    </body>
  </worldbody>
  <actuator>
    <motor name="bucket_joint_0" joint="bucket_joint_0" ctrllimited="true" ctrlrange="-1 1" gear="10" />
  </actuator>
</mujoco>