<mujoco model="partnet_4589">
  <default>
    <default class="display">
      <mesh scale="0.4 0.4 0.4" />
      <joint limited="true" damping="0.01" armature="0.01" frictionloss="0.01" />
      <motor ctrllimited="true" />
      <equality solref="0.001 2" />
      <default class="display/visual">
        <geom condim="1" contype="0" conaffinity="0" group="2" />
      </default>
      <default class="display/collision">
        <geom condim="4" contype="1" conaffinity="14" friction="0.9 0.2 0.2" solref="0.001 2" group="3" />
      </default>
    </default>
  </default>
  <asset>
    <material name="display_original-15_material_0_0" specular="0.06666666666666667" shininess="0.03" rgba="0.11372549019607843 0.11372549019607843 0.11372549019607843 1" />
    <mesh file="display/textured_objs_thickness/original-15/original-15.obj" name="display_original-15"  scale="0.4 0.4 0.4" />
    <material name="display_original-5_material_0_0" specular="0.06666666666666667" shininess="0.03" rgba="0.11372549019607843 0.11372549019607843 0.11372549019607843 1" />
    <mesh file="display/textured_objs_thickness/original-5/original-5.obj" name="display_original-5"  scale="0.4 0.4 0.4" />
    <material name="display_original-10_material_0_0" specular="0.06666666666666667" shininess="0.03" rgba="0.11372549019607843 0.11372549019607843 0.11372549019607843 1" />
    <mesh file="display/textured_objs_thickness/original-10/original-10.obj" name="display_original-10"  scale="0.4 0.4 0.4" />
    <material name="display_original-8_material_0_0" specular="0.06666666666666667" shininess="0.03" rgba="0.11372549019607843 0.11372549019607843 0.11372549019607843 1" />
    <mesh file="display/textured_objs_thickness/original-8/original-8.obj" name="display_original-8"  scale="0.4 0.4 0.4" />
    <material name="display_new-1_material-0" specular="0.06666666666666667" shininess="0.03" rgba="0.11372549019607843 0.11372549019607843 0.11372549019607843 1" />
    <mesh file="display/textured_objs_thickness/new-1/new-1.obj" name="display_new-1"  scale="0.4 0.4 0.4" />
    <material name="display_original-9_material_0_0" specular="0.06666666666666667" shininess="0.03" rgba="0.11372549019607843 0.11372549019607843 0.11372549019607843 1" />
    <mesh file="display/textured_objs_thickness/original-9/original-9.obj" name="display_original-9"  scale="0.4 0.4 0.4" />
    <material name="display_original-4_material_0_0" specular="0.06666666666666667" shininess="0.03" rgba="0.11372549019607843 0.11372549019607843 0.11372549019607843 1" />
    <mesh file="display/textured_objs_thickness/original-4/original-4.obj" name="display_original-4"  scale="0.4 0.4 0.4" />
    <material name="display_original-14_material_0_0" specular="0.06666666666666667" shininess="0.03" rgba="0.11372549019607843 0.11372549019607843 0.11372549019607843 1" />
    <mesh file="display/textured_objs_thickness/original-14/original-14.obj" name="display_original-14"  scale="0.4 0.4 0.4" />
    <material name="display_original-6_material_0_0" specular="0.06666666666666667" shininess="0.03" rgba="0.11372549019607843 0.11372549019607843 0.11372549019607843 1" />
    <mesh file="display/textured_objs_thickness/original-6/original-6.obj" name="display_original-6"  scale="0.4 0.4 0.4" />
    <material name="display_original-11_material_0_0" specular="0.06666666666666667" shininess="0.03" rgba="0.11372549019607843 0.11372549019607843 0.11372549019607843 1" />
    <mesh file="display/textured_objs_thickness/original-11/original-11.obj" name="display_original-11"  scale="0.4 0.4 0.4" />
    <material name="display_new-0_material-0" specular="0.06666666666666667" shininess="0.03" rgba="0.11372549019607843 0.11372549019607843 0.11372549019607843 1" />
    <mesh file="display/textured_objs_thickness/new-0/new-0.obj" name="display_new-0"  scale="0.4 0.4 0.4" />
    <material name="display_original-3_material_0_0" specular="0.06666666666666667" shininess="0.03" rgba="0.11372549019607843 0.11372549019607843 0.11372549019607843 1" />
    <mesh file="display/textured_objs_thickness/original-3/original-3.obj" name="display_original-3"  scale="0.4 0.4 0.4" />
  </asset>
  <worldbody>
    <light directional="true" pos="0 0 0.05" dir="0 0 -1" castshadow="false" />
    <body name="display_link_1" pos="0.2 0.3 1.16" quat="0.4999999999999998 0.5 -0.5000000000000002 -0.5" childclass="display">
      <freejoint name="display_root" />
      <geom name="display_geom" pos="0.0 0.0 0.0" quat="1 0 0 0" type="mesh" mesh="display_original-15" material="display_original-15_material_0_0" density="100" class="display/visual" />
      <geom pos="0.0 0.0 0.0" quat="1 0 0 0" type="mesh" mesh="display_original-14" material="display_original-14_material_0_0" density="0" class="display/visual" />
      <geom pos="0.0 0.0 0.0" quat="1 0 0 0" type="mesh" mesh="display_original-15" material="display_original-15_material_0_0" class="display/collision" />
      <geom pos="0.0 0.0 0.0" quat="1 0 0 0" type="mesh" mesh="display_original-14" material="display_original-14_material_0_0" class="display/collision" />
      <body name="display_link_0" pos="0.009387200000000063 -0.015523215990950332 -0.007618436310905705">
        <joint name="joint_0" pos="0 0 0" axis="-1 0 0" range="-0.0 0.4363323129985824" type="hinge" />
        <geom pos="-0.009387200000000063 0.015523215990950332 0.007618436310905705" quat="1 0 0 0" type="mesh" mesh="display_original-4" material="display_original-4_material_0_0" density="0" class="display/visual" />
        <geom pos="-0.009387200000000063 0.015523215990950332 0.007618436310905705" quat="1 0 0 0" type="mesh" mesh="display_original-3" material="display_original-3_material_0_0" density="0" class="display/visual" />
        <geom pos="-0.009387200000000063 0.015523215990950332 0.007618436310905705" quat="1 0 0 0" type="mesh" mesh="display_new-1" material="display_new-1_material-0" density="0" class="display/visual" />
        <geom pos="-0.009387200000000063 0.015523215990950332 0.007618436310905705" quat="1 0 0 0" type="mesh" mesh="display_original-5" material="display_original-5_material_0_0" density="0" class="display/visual" />
        <geom pos="-0.009387200000000063 0.015523215990950332 0.007618436310905705" quat="1 0 0 0" type="mesh" mesh="display_original-6" material="display_original-6_material_0_0" density="0" class="display/visual" />
        <geom pos="-0.009387200000000063 0.015523215990950332 0.007618436310905705" quat="1 0 0 0" type="mesh" mesh="display_original-8" material="display_original-8_material_0_0" density="0" class="display/visual" />
        <geom pos="-0.009387200000000063 0.015523215990950332 0.007618436310905705" quat="1 0 0 0" type="mesh" mesh="display_original-9" material="display_original-9_material_0_0" density="0" class="display/visual" />
        <geom pos="-0.009387200000000063 0.015523215990950332 0.007618436310905705" quat="1 0 0 0" type="mesh" mesh="display_original-10" material="display_original-10_material_0_0" density="0" class="display/visual" />
        <geom pos="-0.009387200000000063 0.015523215990950332 0.007618436310905705" quat="1 0 0 0" type="mesh" mesh="display_original-11" material="display_original-11_material_0_0" density="0" class="display/visual" />
        <geom pos="-0.009387200000000063 0.015523215990950332 0.007618436310905705" quat="1 0 0 0" type="mesh" mesh="display_new-0" material="display_new-0_material-0" density="0" class="display/visual" />
        <geom pos="-0.009387200000000063 0.015523215990950332 0.007618436310905705" quat="1 0 0 0" type="mesh" mesh="display_original-4" material="display_original-4_material_0_0" class="display/collision" />
        <geom pos="-0.009387200000000063 0.015523215990950332 0.007618436310905705" quat="1 0 0 0" type="mesh" mesh="display_original-3" material="display_original-3_material_0_0" class="display/collision" />
        <geom pos="-0.009387200000000063 0.015523215990950332 0.007618436310905705" quat="1 0 0 0" type="mesh" mesh="display_new-1" material="display_new-1_material-0" class="display/collision" />
        <geom pos="-0.009387200000000063 0.015523215990950332 0.007618436310905705" quat="1 0 0 0" type="mesh" mesh="display_original-5" material="display_original-5_material_0_0" class="display/collision" />
        <geom pos="-0.009387200000000063 0.015523215990950332 0.007618436310905705" quat="1 0 0 0" type="mesh" mesh="display_original-6" material="display_original-6_material_0_0" class="display/collision" />
        <geom pos="-0.009387200000000063 0.015523215990950332 0.007618436310905705" quat="1 0 0 0" type="mesh" mesh="display_original-8" material="display_original-8_material_0_0" class="display/collision" />
        <geom pos="-0.009387200000000063 0.015523215990950332 0.007618436310905705" quat="1 0 0 0" type="mesh" mesh="display_original-9" material="display_original-9_material_0_0" class="display/collision" />
        <geom pos="-0.009387200000000063 0.015523215990950332 0.007618436310905705" quat="1 0 0 0" type="mesh" mesh="display_original-10" material="display_original-10_material_0_0" class="display/collision" />
        <geom pos="-0.009387200000000063 0.015523215990950332 0.007618436310905705" quat="1 0 0 0" type="mesh" mesh="display_original-11" material="display_original-11_material_0_0" class="display/collision" />
        <geom pos="-0.009387200000000063 0.015523215990950332 0.007618436310905705" quat="1 0 0 0" type="mesh" mesh="display_new-0" material="display_new-0_material-0" class="display/collision" />
      </body>
    </body>
  </worldbody>
  <actuator>
    <motor name="joint_0" joint="joint_0" ctrllimited="true" ctrlrange="-1 1" gear="1" />
  </actuator>
</mujoco>
