<mujoco model="glass">
  <compiler angle="radian" eulerseq="zyx" autolimits="true" />
  <default>
    <default class="glass">
    <mesh scale="0.2 0.2 0.2" />
    <joint limited="true" damping="0.01" armature="0.01" frictionloss="0.01" />
    <motor ctrllimited="true" />
    <equality solref="0.001 2" />
    <default class="glass/visual">
      <geom condim="1" contype="0" conaffinity="0" group="2" />
    </default>
    <default class="glass/collision">
      <geom condim="4" contype="1" conaffinity="14" friction="0.9 0.2 0.2" solref="0.001 2" group="3" />
    </default>
  </default>
  </default>
  <asset>
    <material name="glass_original-2_material_0_0" specular="0.06666666666666667" shininess="0.03" rgba="0.11372549019607843 0.11372549019607843 0.11372549019607843 1" />
    <mesh file="glass/textured_objs_thickness/original-2/original-2.obj" name="glass_original-2" scale="0.2 0.2 0.2"/>
    <material name="glass_original-1_1_material_0_0" specular="0.06666666666666667" shininess="0.03" rgba="0.11372549019607843 0.11372549019607843 0.11372549019607843 1" />
    <material name="glass_original-1_0_material_1_0" specular="0.06666666666666667" shininess="0.03" rgba="0 0 0 1" />
    <mesh file="glass/textured_objs_thickness/original-1/original-1_0.obj" name="glass_original-1_0" scale="0.2 0.2 0.2"/>
    <mesh file="glass/textured_objs_thickness/original-1/original-1_1.obj" name="glass_original-1_1" scale="0.2 0.2 0.2"/>
    <material name="glass_original-3_material_0_0" specular="0.06666666666666667" shininess="0.03" rgba="0.11372549019607843 0.11372549019607843 0.11372549019607843 1" />
    <mesh file="glass/textured_objs_thickness/original-3/original-3.obj" name="glass_original-3" scale="0.2 0.2 0.2"/>
  </asset>
  <worldbody>
    <light directional="true" pos="0 0 0.05" dir="0 0 -1" castshadow="false" />
    <body name="glass" pos="-0.25 -0.25 0.98" quat="0.5 0.5 -0.5 -0.5" childclass="glass">
      <freejoint name="glass_root" />
      <geom pos="0.0 0.0 0.0" quat="1 0 0 0" type="mesh" mesh="glass_original-1_0" material="glass_original-1_0_material_1_0" density="0" class="glass/visual" />
      <geom pos="0.0 0.0 0.0" quat="1 0 0 0" type="mesh" mesh="glass_original-1_1" material="glass_original-1_1_material_0_0" density="0" class="glass/visual" />
      <geom pos="0.0 0.0 0.0" quat="1 0 0 0" type="mesh" mesh="glass_original-1_0" material="glass_original-1_0_material_1_0" mass="0.01" class="glass/collision" />
      <geom pos="0.0 0.0 0.0" quat="1 0 0 0" type="mesh" mesh="glass_original-1_1" material="glass_original-1_1_material_0_0" mass="0.01" class="glass/collision" />
      <body name="link_0" pos="-0.05822870119362571 0.012772445263971878 0.025211727978494827">
        <joint name="glass_joint_0" pos="-0.057 0 0.027" axis="0 -1 0" range="0.2 1.3823007675795087" damping="0.1" type="hinge" limited="true" />
        <geom pos="0.05822870119362571 -0.012772445263971878 -0.025211727978494827" quat="1 0 0 0" type="mesh" mesh="glass_original-3" mass="0.01" material="glass_original-3_material_0_0" density="0" class="glass/visual" />
        <geom pos="0.05822870119362571 -0.012772445263971878 -0.025211727978494827" quat="1 0 0 0" type="mesh" mesh="glass_original-3" mass="0.01" material="glass_original-3_material_0_0" class="glass/collision" />
      </body>
      <body name="link_1" pos="0.06172104681835892 0.012821442256062455 0.025883854335217473">
        <joint name="glass_joint_1" pos="0.062 0 0.027" axis="0 1 0" range="0.2 1.2915436464758039" damping="0.1" type="hinge" limited="true" />
        <geom pos="-0.06172104681835892 -0.012821442256062455 -0.025883854335217473" quat="1 0 0 0" type="mesh" mesh="glass_original-2" material="glass_original-2_material_0_0" density="0" class="glass/visual" />
        <geom pos="-0.06172104681835892 -0.012821442256062455 -0.025883854335217473" quat="1 0 0 0" type="mesh" mesh="glass_original-2" mass="0.01" material="glass_original-2_material_0_0" class="glass/collision" />
      </body>
    </body>
  </worldbody>
  <actuator>
    <motor name="glass_joint_0" joint="glass_joint_0" ctrllimited="true" ctrlrange="-1 1" gear="1" />
    <motor name="glass_joint_1" joint="glass_joint_1" ctrllimited="true" ctrlrange="-1 1" gear="1" />
  </actuator>
</mujoco>
