<?xml version='1.0' encoding='utf-8'?>
<mujoco model="panda_allegro">
  <compiler angle="radian" autolimits="true" />
  <option timestep=".002" noslip_iterations="5" noslip_tolerance="0" />

  <default>
    <default class="panda_right">
      <joint armature="0.1" damping="1" axis="0 0 1" range="-2.8973 2.8973" />
      <default class="panda/visual_right">
        <geom type="mesh" contype="0" conaffinity="0" group="2" />
      </default>
      <default class="panda/collision_right">
        <geom type="mesh" group="3" />
      </default>
      <site size="0.001" rgba="0.5 0.5 0.5 0.3" group="4" />
    </default>
    <default class="2f85_right">
      <mesh scale="0.001 0.001 0.001" />
      <general biastype="affine" />
      <site type="sphere" rgba="0.9 0.9 0.9 1" size="0.005" group="4" />
      <joint axis="1 0 0" />
      <default class="driver_right">
        <joint range="0 0.8" armature="0.005" damping="0.1" solimplimit="0.95 0.99 0.001" solreflimit="0.005 1" />
      </default>
      <default class="follower_right">
        <joint range="-0.872664 0.872664" pos="0 -0.018 0.0065" solimplimit="0.95 0.99 0.001" solreflimit="0.005 1" />
      </default>
      <default class="spring_link_right">
        <joint range="-0.29670597283 0.8" stiffness="0.05" springref="2.62" damping="0.00125" />
      </default>
      <default class="coupler_right">
        <joint range="-1.57 0" solimplimit="0.95 0.99 0.001" solreflimit="0.005 1" />
      </default>
      <default class="2f85/visual_right">
        <geom type="mesh" contype="0" conaffinity="0" group="2" />
      </default>
      <default class="2f85/collision_right">
        <geom type="mesh" group="3" />
        <default class="pad_box1_right">
          <geom mass="0" type="box" pos="0 -0.0026 0.028125" size="0.011 0.004 0.009375" friction="0.7" solimp="0.95 0.99 0.001" solref="0.004 1" priority="1" rgba="0.55 0.55 0.55 1" />
        </default>
        <default class="pad_box2_right">
          <geom mass="0" type="box" pos="0 -0.0026 0.009375" size="0.011 0.004 0.009375" friction="0.6" solimp="0.95 0.99 0.001" solref="0.004 1" priority="1" rgba="0.45 0.45 0.45 1" />
        </default>
      </default>
    </default>
  </default>

  <default>
    <default class="allegro_right">
      <joint axis="0 1 0" damping=".1" />
      <position kp="1" />
      <geom density="800" />

      <default class="visual_right">
        <geom type="mesh" contype="0" conaffinity="0" group="2" material="black_right" />
        <default class="palm_visual_right">
          <geom mesh="base_link_right" />
        </default>
        <default class="base_visual_right">
          <geom mesh="link_0.0_right" />
        </default>
        <default class="proximal_visual_right">
          <geom mesh="link_1.0_right" />
        </default>
        <default class="medial_visual_right">
          <geom mesh="link_2.0_right" />
        </default>
        <default class="distal_visual_right">
          <geom mesh="link_3.0_right" />
        </default>
        <default class="fingertip_visual_right">
          <geom pos="0 0 0.0267" material="white_right" mesh="link_3.0_tip_right" />
        </default>
        <default class="thumbtip_visual_right">
          <geom pos="0 0 0.0423" material="white_right" mesh="link_15.0_tip_right" />
        </default>
      </default>

      <default class="collision_right">
        <geom group="3" type="box" mass="0" />
        <default class="palm_collision_right">
          <geom size="0.0204 0.0565 0.0475" pos="-0.0093 0 -0.0475" />
        </default>
        <default class="base_collision_right">
          <geom size="0.0098 0.01375 0.0082" pos="0 0 0.0082" />
          <default class="thumb_base_collision_right">
            <geom size="0.0179 0.017 0.02275" pos="-0.0179 0.009 0.0145" />
          </default>
        </default>
        <default class="proximal_collision_right">
          <geom size="0.0098 0.01375 0.027" pos="0 0 0.027" />
          <default class="thumb_proximal_collision_right">
            <geom size="0.0098 0.01375 0.00885" pos="0 0 0.00885" />
          </default>
        </default>
        <default class="medial_collision_right">
          <geom size="0.0098 0.01375 0.0192" pos="0 0 0.0192" />
          <default class="thumb_medial_collision_right">
            <geom size="0.0098 0.01375 0.0257" pos="0 0 0.0257" />
          </default>
        </default>
        <default class="distal_collision_right">
          <geom size="0.0098 0.01375 0.008" pos="0 0 0.008" />
          <default class="thumb_distal_collision_right">
            <geom size="0.0098 0.01375 0.0157" pos="0 0 0.0157" />
          </default>
        </default>
        <default class="fingertip_collision_right">
          <geom type="capsule" size="0.012 0.01" pos="0 0 0.019" />
          <default class="thumbtip_collision_right">
            <geom type="capsule" size="0.012 0.008" pos="0 0 0.035" />
          </default>
        </default>
      </default>

      <default class="base_right">
        <joint axis="0 0 1" range="-0.47 0.47" />
        <position ctrlrange="-0.47 0.47" />
      </default>
      <default class="proximal_right">
        <joint range="-0.196 1.61" />
        <position ctrlrange="-0.196 1.61" />
      </default>
      <default class="medial_right">
        <joint range="-0.174 1.709" />
        <position ctrlrange="-0.174 1.709" />
      </default>
      <default class="distal_right">
        <joint range="-0.227 1.618" />
        <position ctrlrange="-0.227 1.618" />
      </default>
      <default class="thumb_base_right">
        <joint axis="-1 0 0" range="0.263 1.396" />
        <position ctrlrange="0.263 1.396" />
      </default>
      <default class="thumb_proximal_right">
        <joint axis="0 0 1" range="-0.105 1.163" />
        <position ctrlrange="-0.105 1.163" />
      </default>
      <default class="thumb_medial_right">
        <joint range="-0.189 1.644" />
        <position ctrlrange="-0.189 1.644" />
      </default>
      <default class="thumb_distal_right">
        <joint range="-0.162 1.719" />
        <position ctrlrange="-0.162 1.719" />
      </default>
    </default>
  </default>

  <asset>
    <material name="white_right" rgba="1 1 1 1" />
    <material name="off_white_right" rgba="0.901961 0.921569 0.929412 1" />
    <material name="dark_grey_right" rgba="0.25 0.25 0.25 1" />
    <material name="green_right" rgba="0 1 0 1" />
    <material name="light_blue_right" rgba="0.039216 0.541176 0.780392 1" />
    <material name="metal_right" rgba="0.58 0.58 0.58 1" />
    <material name="silicone_right" rgba="0.1882 0.1882 0.1882 1" />
    <material name="gray_right" rgba="0.4627 0.4627 0.4627 1" />
    <material name="black_right" rgba="0.149 0.149 0.149 1" />

    <mesh name="link0_c_right" file="franka_emika_panda/assets/link0.stl" />
    <mesh name="link1_c_right" file="franka_emika_panda/assets/link1.stl" />
    <mesh name="link2_c_right" file="franka_emika_panda/assets/link2.stl" />
    <mesh name="link3_c_right" file="franka_emika_panda/assets/link3.stl" />
    <mesh name="link4_c_right" file="franka_emika_panda/assets/link4.stl" />
    <mesh name="link5_c0_right" file="franka_emika_panda/assets/link5_collision_0.obj" />
    <mesh name="link5_c1_right" file="franka_emika_panda/assets/link5_collision_1.obj" />
    <mesh name="link5_c2_right" file="franka_emika_panda/assets/link5_collision_2.obj" />
    <mesh name="link6_c_right" file="franka_emika_panda/assets/link6.stl" />
    <mesh name="link7_c_right" file="franka_emika_panda/assets/link7.stl" />
    <mesh file="franka_emika_panda/assets/link0_0.obj" name="link0_0_right" />
    <mesh file="franka_emika_panda/assets/link0_1.obj" name="link0_1_right" />
    <mesh file="franka_emika_panda/assets/link0_2.obj" name="link0_2_right" />
    <mesh file="franka_emika_panda/assets/link0_3.obj" name="link0_3_right" />
    <mesh file="franka_emika_panda/assets/link0_4.obj" name="link0_4_right" />
    <mesh file="franka_emika_panda/assets/link0_5.obj" name="link0_5_right" />
    <mesh file="franka_emika_panda/assets/link0_7.obj" name="link0_7_right" />
    <mesh file="franka_emika_panda/assets/link0_8.obj" name="link0_8_right" />
    <mesh file="franka_emika_panda/assets/link0_9.obj" name="link0_9_right" />
    <mesh file="franka_emika_panda/assets/link0_10.obj" name="link0_10_right" />
    <mesh file="franka_emika_panda/assets/link0_11.obj" name="link0_11_right" />
    <mesh file="franka_emika_panda/assets/link1.obj" name="link1_right" />
    <mesh file="franka_emika_panda/assets/link2.obj" name="link2_right" />
    <mesh file="franka_emika_panda/assets/link3_0.obj" name="link3_0_right" />
    <mesh file="franka_emika_panda/assets/link3_1.obj" name="link3_1_right" />
    <mesh file="franka_emika_panda/assets/link3_2.obj" name="link3_2_right" />
    <mesh file="franka_emika_panda/assets/link3_3.obj" name="link3_3_right" />
    <mesh file="franka_emika_panda/assets/link4_0.obj" name="link4_0_right" />
    <mesh file="franka_emika_panda/assets/link4_1.obj" name="link4_1_right" />
    <mesh file="franka_emika_panda/assets/link4_2.obj" name="link4_2_right" />
    <mesh file="franka_emika_panda/assets/link4_3.obj" name="link4_3_right" />
    <mesh file="franka_emika_panda/assets/link5_0.obj" name="link5_0_right" />
    <mesh file="franka_emika_panda/assets/link5_1.obj" name="link5_1_right" />
    <mesh file="franka_emika_panda/assets/link5_2.obj" name="link5_2_right" />
    <mesh file="franka_emika_panda/assets/link6_0.obj" name="link6_0_right" />
    <mesh file="franka_emika_panda/assets/link6_1.obj" name="link6_1_right" />
    <mesh file="franka_emika_panda/assets/link6_2.obj" name="link6_2_right" />
    <mesh file="franka_emika_panda/assets/link6_3.obj" name="link6_3_right" />
    <mesh file="franka_emika_panda/assets/link6_4.obj" name="link6_4_right" />
    <mesh file="franka_emika_panda/assets/link6_5.obj" name="link6_5_right" />
    <mesh file="franka_emika_panda/assets/link6_6.obj" name="link6_6_right" />
    <mesh file="franka_emika_panda/assets/link6_7.obj" name="link6_7_right" />
    <mesh file="franka_emika_panda/assets/link6_8.obj" name="link6_8_right" />
    <mesh file="franka_emika_panda/assets/link6_9.obj" name="link6_9_right" />
    <mesh file="franka_emika_panda/assets/link6_10.obj" name="link6_10_right" />
    <mesh file="franka_emika_panda/assets/link6_11.obj" name="link6_11_right" />
    <mesh file="franka_emika_panda/assets/link6_12.obj" name="link6_12_right" />
    <mesh file="franka_emika_panda/assets/link6_13.obj" name="link6_13_right" />
    <mesh file="franka_emika_panda/assets/link6_14.obj" name="link6_14_right" />
    <mesh file="franka_emika_panda/assets/link6_15.obj" name="link6_15_right" />
    <mesh file="franka_emika_panda/assets/link6_16.obj" name="link6_16_right" />
    <mesh file="franka_emika_panda/assets/link7_0.obj" name="link7_0_right" />
    <mesh file="franka_emika_panda/assets/link7_1.obj" name="link7_1_right" />
    <mesh file="franka_emika_panda/assets/link7_2.obj" name="link7_2_right" />
    <mesh file="franka_emika_panda/assets/link7_3.obj" name="link7_3_right" />
    <mesh file="franka_emika_panda/assets/link7_4.obj" name="link7_4_right" />
    <mesh file="franka_emika_panda/assets/link7_5.obj" name="link7_5_right" />
    <mesh file="franka_emika_panda/assets/link7_6.obj" name="link7_6_right" />
    <mesh file="franka_emika_panda/assets/link7_7.obj" name="link7_7_right" />

    <material name="allegro_black_right" rgba="0.2 0.2 0.2 1" />
    <material name="allegro_white_right" rgba="0.9 0.9 0.9 1" />
    <mesh file="wonik_allegro/assets/base_link.stl" name="base_link_right" />
    <mesh file="wonik_allegro/assets/link_0.0.stl" name="link_0.0_right" />
    <mesh file="wonik_allegro/assets/link_1.0.stl" name="link_1.0_right" />
    <mesh file="wonik_allegro/assets/link_2.0.stl" name="link_2.0_right" />
    <mesh file="wonik_allegro/assets/link_3.0.stl" name="link_3.0_right" />
    <mesh file="wonik_allegro/assets/link_3.0_tip.stl" name="link_3.0_tip_right" />
    <mesh file="wonik_allegro/assets/link_12.0_right.stl" name="link_12.0_right" />
    <mesh file="wonik_allegro/assets/link_13.0.stl" name="link_13.0_right" />
    <mesh file="wonik_allegro/assets/link_14.0.stl" name="link_14.0_right" />
    <mesh file="wonik_allegro/assets/link_15.0.stl" name="link_15.0_right" />
    <mesh file="wonik_allegro/assets/link_15.0_tip.stl" name="link_15.0_tip_right" />

    <!-- rethink base assets -->
    <mesh name="pedestal_right" file="rethink_mount/pedestal.stl" />
  </asset>
  
  <worldbody>
    <body name="base_right" pos="-0.8 -0.4 0.924">
      <body name="controller_box_right" pos="0 0 0">
        <inertial diaginertia="1.71363 1.27988 0.809981" mass="46.64" pos="-0.325 0 -0.38"/>
        <geom pos="-0.325 0 -0.38" size="0.11 0.2 0.265" type="box" name="controller_box_col_right" group="3"/>
      </body>
      <body name="pedestal_feet_right" pos="0 0 0">
        <inertial diaginertia="8.16095 9.59375 15.0785" mass="167.09" pos="-0.1225 0 -0.758"/>
        <geom pos="-0.1225 0 -0.758" size="0.385 0.35 0.155" type="box" name="pedestal_feet_col_right" group="3"/>
      </body>
      <body name="torso_right" pos="0 0 0">
        <inertial diaginertia="1e-08 1e-08 1e-08" mass="0.0001" pos="0 0 0"/>
        <geom conaffinity="0" contype="0" group="1" pos="0 0 -0.05" size="0.05 0.05 0.05" type="box" name="torso_vis_right" rgba="0.2 0.2 0.2 1" />
      </body>
      <body name="pedestal_right" pos="0 0 0">
        <inertial diaginertia="6.0869 5.81635 4.20915" mass="60.864" pos="0 0 0" quat="0.659267 -0.259505 -0.260945 0.655692"/>
        <geom conaffinity="0" contype="0" group="1" mesh="pedestal_right" type="mesh" name="pedestal_vis_right" rgba="0.2 0.2 0.2 1" />
        <geom pos="-0.02 0 -0.29" rgba="0.2 0.2 0.2 1" size="0.18 0.31" type="cylinder" name="pedestal_col_right" group="3"/>
      </body>
      <body name="world_frame_right" pos="0 0 0">
      </body>

      <body name="link0_right" childclass="panda_right" pos="0.05 0 0">
      <inertial mass="0.629769" pos="0 0 0" fullinertia="0.00315 0.00388 0.004285 8.2904e-7 0.00015 8.2299e-6" />
      <geom mesh="link0_0_right" material="off_white_right" class="panda/visual_right" />
      <geom mesh="link0_1_right" material="dark_grey_right" class="panda/visual_right" />
      <geom mesh="link0_2_right" material="off_white_right" class="panda/visual_right" />
      <geom mesh="link0_3_right" material="dark_grey_right" class="panda/visual_right" />
      <geom mesh="link0_4_right" material="off_white_right" class="panda/visual_right" />
      <geom mesh="link0_5_right" material="dark_grey_right" class="panda/visual_right" />
      <geom mesh="link0_7_right" material="white_right" class="panda/visual_right" />
      <geom mesh="link0_8_right" material="white_right" class="panda/visual_right" />
      <geom mesh="link0_9_right" material="dark_grey_right" class="panda/visual_right" />
      <geom mesh="link0_10_right" material="off_white_right" class="panda/visual_right" />
      <geom mesh="link0_11_right" material="white_right" class="panda/visual_right" />
      <geom mesh="link0_c_right" class="panda/collision_right" />
      <body name="link1_right" pos="0 0 0.333">
        <inertial mass="4.970684" pos="0.003875 0.002081 -0.04762" fullinertia="0.70337 0.70661 0.0091170 -0.00013900 0.0067720 0.019169" />
        <joint name="joint1_right" />
        <site name="joint1_right" />
        <geom material="white_right" mesh="link1_right" class="panda/visual_right" />
        <geom mesh="link1_c_right" class="panda/collision_right" />
        <body name="link2_right" quat="1 -1 0 0">
          <inertial mass="0.646926" pos="-0.003141 -0.02872 0.003495" fullinertia="0.0079620 2.8110e-2 2.5995e-2 -3.925e-3 1.0254e-2 7.04e-4" />
          <joint name="joint2_right" range="-1.7628 1.7628" />
          <site name="joint2_right" />
          <geom material="white_right" mesh="link2_right" class="panda/visual_right" />
          <geom mesh="link2_c_right" class="panda/collision_right" />
          <body name="link3_right" pos="0 -0.316 0" quat="1 1 0 0">
            <inertial mass="3.228604" pos="2.7518e-2 3.9252e-2 -6.6502e-2" fullinertia="3.7242e-2 3.6155e-2 1.083e-2 -4.761e-3 -1.1396e-2 -1.2805e-2" />
            <joint name="joint3_right" />
            <site name="joint3_right" />
            <geom mesh="link3_0_right" material="white_right" class="panda/visual_right" />
            <geom mesh="link3_1_right" material="white_right" class="panda/visual_right" />
            <geom mesh="link3_2_right" material="white_right" class="panda/visual_right" />
            <geom mesh="link3_3_right" material="dark_grey_right" class="panda/visual_right" />
            <geom mesh="link3_c_right" class="panda/collision_right" />
            <body name="link4_right" pos="0.0825 0 0" quat="1 1 0 0">
              <inertial mass="3.587895" pos="-5.317e-2 1.04419e-1 2.7454e-2" fullinertia="2.5853e-2 1.9552e-2 2.8323e-2 7.796e-3 -1.332e-3 8.641e-3" />
              <joint name="joint4_right" range="-3.0718 -0.0698" />
              <site name="joint4_right" />
              <geom mesh="link4_0_right" material="white_right" class="panda/visual_right" />
              <geom mesh="link4_1_right" material="white_right" class="panda/visual_right" />
              <geom mesh="link4_2_right" material="dark_grey_right" class="panda/visual_right" />
              <geom mesh="link4_3_right" material="white_right" class="panda/visual_right" />
              <geom mesh="link4_c_right" class="panda/collision_right" />
              <body name="link5_right" pos="-0.0825 0.384 0" quat="1 -1 0 0">
                <inertial mass="1.225946" pos="-1.1953e-2 4.1065e-2 -3.8437e-2" fullinertia="3.5549e-2 2.9474e-2 8.627e-3 -2.117e-3 -4.037e-3 2.29e-4" />
                <joint name="joint5_right" />
                <site name="joint5_right" />
                <geom mesh="link5_0_right" material="dark_grey_right" class="panda/visual_right" />
                <geom mesh="link5_1_right" material="white_right" class="panda/visual_right" />
                <geom mesh="link5_2_right" material="white_right" class="panda/visual_right" />
                <geom mesh="link5_c0_right" class="panda/collision_right" />
                <geom mesh="link5_c1_right" class="panda/collision_right" />
                <geom mesh="link5_c2_right" class="panda/collision_right" />
                <body name="link6_right" quat="1 1 0 0">
                  <inertial mass="1.666555" pos="6.0149e-2 -1.4117e-2 -1.0517e-2" fullinertia="1.964e-3 4.354e-3 5.433e-3 1.09e-4 -1.158e-3 3.41e-4" />
                  <joint name="joint6_right" range="-0.0175 3.7525" />
                  <site name="joint6_right" />
                  <geom mesh="link6_0_right" material="off_white_right" class="panda/visual_right" />
                  <geom mesh="link6_1_right" material="white_right" class="panda/visual_right" />
                  <geom mesh="link6_2_right" material="dark_grey_right" class="panda/visual_right" />
                  <geom mesh="link6_3_right" material="white_right" class="panda/visual_right" />
                  <geom mesh="link6_4_right" material="white_right" class="panda/visual_right" />
                  <geom mesh="link6_5_right" material="white_right" class="panda/visual_right" />
                  <geom mesh="link6_6_right" material="white_right" class="panda/visual_right" />
                  <geom mesh="link6_7_right" material="light_blue_right" class="panda/visual_right" />
                  <geom mesh="link6_8_right" material="light_blue_right" class="panda/visual_right" />
                  <geom mesh="link6_9_right" material="dark_grey_right" class="panda/visual_right" />
                  <geom mesh="link6_10_right" material="dark_grey_right" class="panda/visual_right" />
                  <geom mesh="link6_11_right" material="white_right" class="panda/visual_right" />
                  <geom mesh="link6_12_right" material="green_right" class="panda/visual_right" />
                  <geom mesh="link6_13_right" material="white_right" class="panda/visual_right" />
                  <geom mesh="link6_14_right" material="dark_grey_right" class="panda/visual_right" />
                  <geom mesh="link6_15_right" material="dark_grey_right" class="panda/visual_right" />
                  <geom mesh="link6_16_right" material="white_right" class="panda/visual_right" />
                  <geom mesh="link6_c_right" class="panda/collision_right" />
                  <body name="link7_right" pos="0.088 0 0" quat="1 1 0 0">
                    <inertial mass="7.35522e-01" pos="1.0517e-2 -4.252e-3 6.1597e-2" fullinertia="1.2516e-2 1.0027e-2 4.815e-3 -4.28e-4 -1.196e-3 -7.41e-4" />
                    <joint name="joint7_right" />
                    <site name="joint7_right" />
                    <geom mesh="link7_0_right" material="white_right" class="panda/visual_right" />
                    <geom mesh="link7_1_right" material="dark_grey_right" class="panda/visual_right" />
                    <geom mesh="link7_2_right" material="dark_grey_right" class="panda/visual_right" />
                    <geom mesh="link7_3_right" material="dark_grey_right" class="panda/visual_right" />
                    <geom mesh="link7_4_right" material="dark_grey_right" class="panda/visual_right" />
                    <geom mesh="link7_5_right" material="dark_grey_right" class="panda/visual_right" />
                    <geom mesh="link7_6_right" material="dark_grey_right" class="panda/visual_right" />
                    <geom mesh="link7_7_right" material="white_right" class="panda/visual_right" />
                    <geom mesh="link7_c_right" class="panda/collision_right" />
                    <body name="attachment_right" pos="0 0 0.107" quat="0.3826834 0 0 0.9238795">
                      <!-- <camera name="handcam_depth_right" pos="-0.05 0 0" fovy="62" quat="0 1 -1 0" /> -->
                      <camera name="handcam_rgb_right" pos="0.14 0.03 0.04" fovy="60" quat="-0.353553 0.612372 -0.612372 0.353553" />
                      <site name="attachment_site_right" quat="0 0 0 1" />
                      <body name="allegro_attachment_right">
                        <body name="allegro_palm_right" pos="-0.05 0.0 0.03" quat="0.707 0 -0.707 0" childclass="allegro_right">
                          <geom class="palm_visual_right" mesh="base_link_right" />
                          <geom class="palm_collision_right" />
                          <body name="ff_base_right" pos="0 0.0435 -0.001542" quat="0.999048 -0.0436194 0 0">
                            <joint name="ffj0_right" class="base_right" />
                            <geom class="base_visual_right" />
                            <geom class="base_collision_right" />
                            <body name="ff_proximal_right" pos="0 0 0.0164">
                              <joint name="ffj1_right" class="proximal_right" />
                              <geom class="proximal_visual_right" />
                              <geom class="proximal_collision_right" />
                              <body name="ff_medial_right" pos="0 0 0.054">
                                <joint name="ffj2_right" class="medial_right" />
                                <geom class="medial_visual_right" />
                                <geom class="medial_collision_right" />
                                <body name="ff_distal_right" pos="0 0 0.0384">
                                  <joint name="ffj3_right" class="distal_right" />
                                  <geom class="distal_visual_right" />
                                  <geom class="distal_collision_right" />
                                  <body name="ff_tip_right">
                                    <geom class="fingertip_visual_right" />
                                    <geom name="fingertip_ff_right" class="fingertip_collision_right" />
                                  </body>
                                </body>
                              </body>
                            </body>
                          </body>

                          <body name="mf_base_right" pos="0 0 0.0007">
                            <joint name="mfj0_right" class="base_right" />
                            <geom class="base_visual_right" />
                            <geom class="base_collision_right" />
                            <body name="mf_proximal_right" pos="0 0 0.0164">
                              <joint name="mfj1_right" class="proximal_right" />
                              <geom class="proximal_visual_right" />
                              <geom class="proximal_collision_right" />
                              <body name="mf_medial_right" pos="0 0 0.054">
                                <joint name="mfj2_right" class="medial_right" />
                                <geom class="medial_visual_right" />
                                <geom class="medial_collision_right" />
                                <body name="mf_distal_right" pos="0 0 0.0384">
                                  <joint name="mfj3_right" class="distal_right" />
                                  <geom class="distal_visual_right" />
                                  <geom class="distal_collision_right" />
                                  <body name="mf_tip_right">
                                    <geom class="fingertip_visual_right" />
                                    <geom name="fingertip_mf_right" class="fingertip_collision_right" />
                                  </body>
                                </body>
                              </body>
                            </body>
                          </body>
                          <body name="rf_base_right" pos="0 -0.0435 -0.001542" quat="0.999048 0.0436194 0 0">
                            <joint name="rfj0_right" class="base_right" />
                            <geom class="base_visual_right" />
                            <geom class="base_collision_right" />
                            <body name="rf_proximal_right" pos="0 0 0.0164">
                              <joint name="rfj1_right" class="proximal_right" />
                              <geom class="proximal_visual_right" />
                              <geom class="proximal_collision_right" />
                              <body name="rf_medial_right" pos="0 0 0.054">
                                <joint name="rfj2_right" class="medial_right" />
                                <geom class="medial_visual_right" />
                                <geom class="medial_collision_right" />
                                <body name="rf_distal_right" pos="0 0 0.0384">
                                  <joint name="rfj3_right" class="distal_right" />
                                  <geom class="distal_visual_right" />
                                  <geom class="distal_collision_right" />
                                  <body name="rf_tip_right">
                                    <geom class="fingertip_visual_right" />
                                    <geom name="fingertip_rf_right" class="fingertip_collision_right" />
                                  </body>
                                </body>
                              </body>
                            </body>
                          </body>
                          <body name="th_base_right" pos="-0.0182 0.019333 -0.045987" quat="0.477714 -0.521334 -0.521334 -0.477714">
                            <joint name="thj0_right" class="thumb_base_right" />
                            <geom class="visual_right" mesh="link_12.0_right" />
                            <geom class="thumb_base_collision_right" />
                            <body name="th_proximal_right" pos="-0.027 0.005 0.0399">
                              <joint name="thj1_right" class="thumb_proximal_right" />
                              <geom class="visual_right" mesh="link_13.0_right" />
                              <geom class="thumb_proximal_collision_right" />
                              <body name="th_medial_right" pos="0 0 0.0177">
                                <joint name="thj2_right" class="thumb_medial_right" />
                                <geom class="visual_right" mesh="link_14.0_right" />
                                <geom class="thumb_medial_collision_right" />
                                <body name="th_distal_right" pos="0 0 0.0514">
                                  <joint name="thj3_right" class="thumb_distal_right" />
                                  <geom class="visual_right" mesh="link_15.0_right" />
                                  <geom class="thumb_distal_collision_right" />
                                  <body name="th_tip_right">
                                    <geom class="thumbtip_visual_right" />
                                    <geom name="thumbtip_right" class="thumbtip_collision_right" />
                                  </body>
                                </body>
                              </body>
                            </body>
                          </body>
                        </body>
                      </body>
                    </body>
                  </body>
                </body>
              </body>
            </body>
          </body>
        </body>
      </body>
    </body>
    </body>
  </worldbody>

  <contact>
    <exclude body1="allegro_palm_right" body2="ff_base_right" />
    <exclude body1="allegro_palm_right" body2="mf_base_right" />
    <exclude body1="allegro_palm_right" body2="rf_base_right" />
    <exclude body1="allegro_palm_right" body2="th_base_right" />
    <exclude body1="allegro_palm_right" body2="th_proximal_right" />
  </contact>

  <actuator>
    <motor class="panda_right" name="actuator1_right" joint="joint1_right" ctrlrange="-87 87" />
    <motor class="panda_right" name="actuator2_right" joint="joint2_right" ctrlrange="-87 87" />
    <motor class="panda_right" name="actuator3_right" joint="joint3_right" ctrlrange="-87 87" />
    <motor class="panda_right" name="actuator4_right" joint="joint4_right" ctrlrange="-87 87" />
    <motor class="panda_right" name="actuator5_right" joint="joint5_right" ctrlrange="-12 12" />
    <motor class="panda_right" name="actuator6_right" joint="joint6_right" ctrlrange="-12 12" />
    <motor class="panda_right" name="actuator7_right" joint="joint7_right" ctrlrange="-12 12" />
    
    <position name="ffa0_right" joint="ffj0_right" class="base_right" />
    <position name="ffa1_right" joint="ffj1_right" class="proximal_right" />
    <position name="ffa2_right" joint="ffj2_right" class="medial_right" />
    <position name="ffa3_right" joint="ffj3_right" class="distal_right" />
    <position name="mfa0_right" joint="mfj0_right" class="base_right" />
    <position name="mfa1_right" joint="mfj1_right" class="proximal_right" />
    <position name="mfa2_right" joint="mfj2_right" class="medial_right" />
    <position name="mfa3_right" joint="mfj3_right" class="distal_right" />
    <position name="rfa0_right" joint="rfj0_right" class="base_right" />
    <position name="rfa1_right" joint="rfj1_right" class="proximal_right" />
    <position name="rfa2_right" joint="rfj2_right" class="medial_right" />
    <position name="rfa3_right" joint="rfj3_right" class="distal_right" />
    <position name="tha0_right" joint="thj0_right" class="thumb_base_right" />
    <position name="tha1_right" joint="thj1_right" class="thumb_proximal_right" />
    <position name="tha2_right" joint="thj2_right" class="thumb_medial_right" />
    <position name="tha3_right" joint="thj3_right" class="thumb_distal_right" />
  </actuator>

  <sensor>
    <jointpos name="panda/joint1_pos_right" joint="joint1_right" />
    <jointpos name="panda/joint2_pos_right" joint="joint2_right" />
    <jointpos name="panda/joint3_pos_right" joint="joint3_right" />
    <jointpos name="panda/joint4_pos_right" joint="joint4_right" />
    <jointpos name="panda/joint5_pos_right" joint="joint5_right" />
    <jointpos name="panda/joint6_pos_right" joint="joint6_right" />
    <jointpos name="panda/joint7_pos_right" joint="joint7_right" />

    <jointvel name="panda/joint1_vel_right" joint="joint1_right" />
    <jointvel name="panda/joint2_vel_right" joint="joint2_right" />
    <jointvel name="panda/joint3_vel_right" joint="joint3_right" />
    <jointvel name="panda/joint4_vel_right" joint="joint4_right" />
    <jointvel name="panda/joint5_vel_right" joint="joint5_right" />
    <jointvel name="panda/joint6_vel_right" joint="joint6_right" />
    <jointvel name="panda/joint7_vel_right" joint="joint7_right" />

    <torque name="panda/joint1_torque_right" site="joint1_right" />
    <torque name="panda/joint2_torque_right" site="joint2_right" />
    <torque name="panda/joint3_torque_right" site="joint3_right" />
    <torque name="panda/joint4_torque_right" site="joint4_right" />
    <torque name="panda/joint5_torque_right" site="joint5_right" />
    <torque name="panda/joint6_torque_right" site="joint6_right" />
    <torque name="panda/joint7_torque_right" site="joint7_right" />

    <force name="panda/wrist_force_right" site="attachment_site_right" />

      <!-- allegro sensors -->
    <jointpos name="allegro_right/ffj0_pos" joint="ffj0_right"/>
    <jointpos name="allegro_right/ffj1_pos" joint="ffj1_right"/>
    <jointpos name="allegro_right/ffj2_pos" joint="ffj2_right"/>
    <jointpos name="allegro_right/ffj3_pos" joint="ffj3_right"/>
    <jointpos name="allegro_right/mfj0_pos" joint="mfj0_right"/>
    <jointpos name="allegro_right/mfj1_pos" joint="mfj1_right"/>
    <jointpos name="allegro_right/mfj2_pos" joint="mfj2_right"/>
    <jointpos name="allegro_right/mfj3_pos" joint="mfj3_right"/>
    <jointpos name="allegro_right/rfj0_pos" joint="rfj0_right"/>
    <jointpos name="allegro_right/rfj1_pos" joint="rfj1_right"/>
    <jointpos name="allegro_right/rfj2_pos" joint="rfj2_right"/>
    <jointpos name="allegro_right/rfj3_pos" joint="rfj3_right"/>
    <jointpos name="allegro_right/thj0_pos" joint="thj0_right"/>
    <jointpos name="allegro_right/thj1_pos" joint="thj1_right"/>
    <jointpos name="allegro_right/thj2_pos" joint="thj2_right"/>
    <jointpos name="allegro_right/thj3_pos" joint="thj3_right"/>

  <framepos name="franka/flange_pos_right" objtype="site" objname="attachment_site_right" />
  <framequat name="franka/flange_quat_right" objtype="site" objname="attachment_site_right" />
  <framelinvel name="franka/flange_vel_right" objtype="site" objname="attachment_site_right" />

  </sensor>

</mujoco>
